<robot name="left_jaw">
    <link name="base"/>
    <link name="l_hand_pitch">
    <inertial>
      <origin xyz="-0.00051677 -0.010462 -0.053422" rpy="0 0 0" />
      <mass value="0.21868931" />
      <inertia ixx="0.00026882" ixy="1.18E-06" ixz="-1.01E-06" iyy="0.00026673" iyz="-6.019E-05" izz="0.00011487" />
    </inertial>
    <visual>
      <origin xyz="0 0 0" rpy="0 0 0" />
      <geometry>
        <mesh filename="../meshes/LArm7.STL" />
      </geometry>
      <material name="">
        <color rgba="0.75294 0.75294 0.75294 1" />
      </material>
    </visual>
    </link>
    <link name="l_link_jaw">
    <inertial>
      <origin xyz="0.00012868 0.0043815 -0.034375" rpy="0 0 0" />
      <mass value="0.06974038" />
      <inertia ixx="5.584E-05" ixy="4E-08" ixz="-3E-07" iyy="7.898E-05" iyz="-3.81E-06" izz="3.272E-05" />
    </inertial>
    <visual>
      <origin xyz="0 0 0" rpy="0 0 0" />
      <geometry>
        <mesh filename="../meshes/LArm8.STL" />
      </geometry>
      <material name="">
        <color rgba="0.75294 0.75294 0.75294 1" />
      </material>
    </visual>
    <collision>
      <origin xyz="0 0 0" rpy="0 0 0" />
      <geometry>
        <sphere radius="0.036" />
      </geometry>
    </collision>
  </link>
  <joint name="l_joint_jaw" type="revolute">
    <origin xyz="0 0 -0.061" rpy="0 0 0" />
    <parent link="l_hand_pitch" />
    <child link="l_link_jaw" />
    <axis xyz="1 0 -1.2211E-05" />
    <limit lower="0" upper="1" effort="3.95" velocity="27.96" />
  </joint>

    <joint name="base_joint" type="fixed">
        <origin xyz="0 0 0" rpy="-1.57 -1.57 0"/>
        <parent link="base"/>
        <child link="l_hand_pitch"/>
    </joint>

    <link name="l_jaw_tip0"/>
  <joint name="l_jaw_tip0_joint" type="fixed">
    <origin
      xyz="0 -0.03 -0.15"
      rpy="0 0 0" />
    <parent
      link="l_hand_pitch"/>
    <child
      link="l_jaw_tip0"/>
  </joint>

    <link name="l_jaw_tip1"/>
    <joint name="l_jaw_tip1_joint" type="fixed">
    <origin
      xyz="0 -0.02 -0.09"
      rpy="0 0 0" />
    <parent
      link="l_link_jaw"/>
    <child
      link="l_jaw_tip1"/>
  </joint>
</robot>